<?xml version="1.0" encoding="utf-8"?>
<!-- This URDF was automatically created by SolidWorks to URDF Exporter! Originally created by Stephen Brawner (brawner@gmail.com) 
     Commit Version: 1.6.0-4-g7f85cfe  Build Version: 1.6.7995.38578
     For more information, please see http://wiki.ros.org/sw_urdf_exporter -->
<robot name="polaris_v2">
  <link name="base_link">
    <inertial>
      <origin xyz="-0.0015058 3.8814E-06 -0.021658" rpy="0 0 0" />
      <mass value="42.453" />
      <inertia
        ixx="2.349"
        ixy="-1.8915E-05"
        ixz="0.019247"
        iyy="3.7739"
        iyz="-1.7304E-13"
        izz="5.1007" />
    </inertial>
    <visual>
      <origin xyz="0 0 0" rpy="0 0 0" />
      <geometry>
        <mesh filename="package://polaris_v2/meshes/base_link.STL" />
      </geometry>
      <material name="White">
        <color rgba="1 1 1 1" />
      </material>
    </visual>
    <collision>
      <origin xyz="0 0 0" rpy="0 0 0" />
      <geometry>
        <mesh filename="package://polaris_v2/meshes/base_link.STL" />
      </geometry>
    </collision>
  </link>
  
  <link
    name="Lidar_Link">
    <inertial>
      <origin xyz="-0.029667 -6.8075E-05 0.0013582" rpy="0 0 0" />
      <mass value="0.055329" />
      <inertia
        ixx="1.8044E-05"
        ixy="3.8843E-08"
        ixz="-2.5259E-07"
        iyy="1.772E-05"
        iyz="-4.9929E-09"
        izz="3.2968E-05" />
    </inertial>
    <visual>
      <origin xyz="0 0 0" rpy="0 0 0" />
      <geometry>
        <mesh filename="package://polaris_v2/meshes/Lidar_Link.STL" />
      </geometry>
      <material name="Black">
        <color rgba="0 0 0 1" />
      </material>
    </visual>
    <collision>
      <origin xyz="0 0 0" rpy="0 0 0" />
      <geometry>
        <mesh filename="package://polaris_v2/meshes/Lidar_Link.STL" />
      </geometry>
    </collision>
  </link>
  <joint name="Lidar_Joint" type="fixed">
    <origin xyz="0.369 -0.0024957 0.20243" rpy="0 0 0" />
    <parent link="base_link" />
    <child link="Lidar_Link" />
    <axis xyz="0 0 0" />
  </joint>
  
  <link name="Camera_Link">
    <inertial>
      <origin xyz="-0.010371 -5.6426E-05 0.00029524" rpy="0 0 0" />
      <mass value="0.041708" />
      <inertia
        ixx="3.212E-05"
        ixy="6.2185E-09"
        ixz="-3.4137E-08"
        iyy="2.8235E-06"
        iyz="1.424E-08"
        izz="3.1609E-05" />
    </inertial>
    <visual>
      <origin xyz="0 0 0" rpy="0 0 0" />
      <geometry>
        <mesh filename="package://polaris_v2/meshes/Camera_Link.STL" />
      </geometry>
      <material name="Gray">
        <color rgba="0.29804 0.29804 0.29804 1" />
      </material>
    </visual>
    <collision>
      <origin xyz="0 0 0" rpy="0 0 0" />
      <geometry>
        <mesh filename="package://polaris_v2/meshes/Camera_Link.STL" />
      </geometry>
    </collision>
  </link>
  <joint name="Camera_Joint" type="fixed">
    <origin xyz="0.40728 -0.0018421 0.15651" rpy="0 0 0" />
    <parent link="base_link" />
    <child link="Camera_Link" />
    <axis xyz="0 0 0" />
  </joint>
  
  <link
    name="Left_Wheel_Link">
    <inertial>
      <origin
        xyz="-5.5511E-17 0 -2.0177E-06"
        rpy="0 0 0" />
      <mass
        value="1.9591" />
      <inertia
        ixx="0.0031213"
        ixy="1.516E-19"
        ixz="1.5917E-20"
        iyy="0.005714"
        iyz="2.081E-19"
        izz="0.0031213" />
    </inertial>
    <visual>
      <origin
        xyz="0 0 0"
        rpy="0 0 0" />
      <geometry>
        <mesh
          filename="package://polaris_v2/meshes/Left_Wheel_Link.STL" />
      </geometry>
      <material
        name="Red">
        <color
          rgba="0.75 0 0 1" />
      </material>
    </visual>
    <collision>
      <origin
        xyz="0 0 0"
        rpy="0 0 0" />
      <geometry>
        <mesh
          filename="package://polaris_v2/meshes/Left_Wheel_Link.STL" />
      </geometry>
    </collision>
  </link>
  <joint
    name="Left_Wheel_Joint"
    type="continuous">
    <origin
      xyz="0.0048092 0.29918 -0.15052"
      rpy="0 0 0" />
    <parent
      link="base_link" />
    <child
      link="Left_Wheel_Link" />
    <axis
      xyz="0 1 0" />
    <limit
      effort="20"
      velocity="15" />
    <dynamics
      damping="0.2"
      friction="0.2" />
  </joint>
  <link
    name="Right_Wheel_Link">
    <inertial>
      <origin
        xyz="5.5511E-17 0 -2.0177E-06"
        rpy="0 0 0" />
      <mass
        value="1.9591" />
      <inertia
        ixx="0.0031213"
        ixy="3.0227E-19"
        ixz="7.3953E-20"
        iyy="0.005714"
        iyz="7.1477E-19"
        izz="0.0031213" />
    </inertial>
    <visual>
      <origin
        xyz="0 0 0"
        rpy="0 0 0" />
      <geometry>
        <mesh
          filename="package://polaris_v2/meshes/Right_Wheel_Link.STL" />
      </geometry>
      <material
        name="Red">
        <color
          rgba="0.75 0 0 1" />
      </material>
    </visual>
    <collision>
      <origin
        xyz="0 0 0"
        rpy="0 0 0" />
      <geometry>
        <mesh
          filename="package://polaris_v2/meshes/Right_Wheel_Link.STL" />
      </geometry>
    </collision>
  </link>
  <joint
    name="Right_Wheel_Joint"
    type="continuous">
    <origin
      xyz="0.0051558 -0.29918 -0.15052"
      rpy="0 0 0" />
    <parent
      link="base_link" />
    <child
      link="Right_Wheel_Link" />
    <axis
      xyz="0 1 0" />
    <limit
      effort="20"
      velocity="1" />
    <dynamics
      damping="0.2"
      friction="0.2" />
  </joint>
  <link
    name="Lifting_Link">
    <inertial>
      <origin
        xyz="-8.9045E-13 -4.6074E-15 -0.019872"
        rpy="0 0 0" />
      <mass
        value="7.1663" />
      <inertia
        ixx="0.11259"
        ixy="6.0508E-07"
        ixz="-2.1825E-18"
        iyy="0.13245"
        iyz="3.3719E-17"
        izz="0.23898" />
    </inertial>
    <visual>
      <origin
        xyz="0 0 0"
        rpy="0 0 0" />
      <geometry>
        <mesh
          filename="package://polaris_v2/meshes/Lifting_Link.STL" />
      </geometry>
      <material
        name="Red">
        <color
          rgba="0.75 0 0 1" />
      </material>
    </visual>
    <collision>
      <origin
        xyz="0 0 0"
        rpy="0 0 0" />
      <geometry>
        <mesh
          filename="package://polaris_v2/meshes/Lifting_Link.STL" />
      </geometry>
    </collision>
  </link>
  <joint
    name="Lifting_Joint"
    type="prismatic">
    <origin
      xyz="0.0012405 0 0.23032"
      rpy="0 0 0" />
    <parent
      link="base_link" />
    <child
      link="Lifting_Link" />
    <axis
      xyz="0 0 1" />
    <limit
      lower="0"
      upper="0.2"
      effort="20"
      velocity="15" />
    <dynamics
      damping="0.2"
      friction="0.2" />
  </joint>
  <link
    name="CS1L">
    <inertial>
      <origin
        xyz="-0.0010118 -2.0245E-05 -0.0079289"
        rpy="0 0 0" />
      <mass
        value="0.012201" />
      <inertia
        ixx="1.3562E-06"
        ixy="1.3591E-08"
        ixz="7.1177E-08"
        iyy="6.7418E-07"
        iyz="1.4266E-09"
        izz="1.6594E-06" />
    </inertial>
    <visual>
      <origin
        xyz="0 0 0"
        rpy="0 0 0" />
      <geometry>
        <mesh
          filename="package://polaris_v2/meshes/CS1L.STL" />
      </geometry>
      <material
        name="Gray">
        <color
          rgba="0.89804 0.91765 0.92941 1" />
      </material>
    </visual>
    <collision>
      <origin
        xyz="0 0 0"
        rpy="0 0 0" />
      <geometry>
        <mesh
          filename="package://polaris_v2/meshes/CS1L.STL" />
      </geometry>
    </collision>
  </link>
  <joint
    name="CS1J"
    type="continuous">
    <origin
      xyz="0.38374 -0.2125 -0.19774"
      rpy="0 0 0" />
    <parent
      link="base_link" />
    <child
      link="CS1L" />
    <axis
      xyz="0 0 1" />
    <limit
      effort="20"
      velocity="15" />
    <dynamics
      damping="0.2"
      friction="0" />
  </joint>
  <link
    name="CW1L">
    <inertial>
      <origin
        xyz="-1.1102E-16 0 0"
        rpy="0 0 0" />
      <mass
        value="0.007684" />
      <inertia
        ixx="5.0437E-07"
        ixy="-1.7782E-09"
        ixz="7.051E-23"
        iyy="5.936E-07"
        iyz="9.8743E-24"
        izz="5.0433E-07" />
    </inertial>
    <visual>
      <origin
        xyz="0 0 0"
        rpy="0 0 0" />
      <geometry>
        <mesh
          filename="package://polaris_v2/meshes/CW1L.STL" />
      </geometry>
      <material
        name="Black">
        <color
          rgba="0 0 0 1" />
      </material>
    </visual>
    <collision>
      <origin
        xyz="0 0 0"
        rpy="0 0 0" />
      <geometry>
        <mesh
          filename="package://polaris_v2/meshes/CW1L.STL" />
      </geometry>
    </collision>
  </link>
  <joint
    name="CW1J"
    type="continuous">
    <origin
      xyz="0.0072628 0.00064477 -0.020775"
      rpy="0 0 0" />
    <parent
      link="CS1L" />
    <child
      link="CW1L" />
    <axis
      xyz="0 1 0" />
    <limit
      effort="20"
      velocity="15" />
    <dynamics
      damping="0.2"
      friction="0" />
  </joint>
  <link
    name="CS2L">
    <inertial>
      <origin
        xyz="0.00098381 -0.00023721 -0.0079289"
        rpy="0 0 0" />
      <mass
        value="0.012201" />
      <inertia
        ixx="1.319E-06"
        ixy="-1.556E-07"
        ixz="-6.9208E-08"
        iyy="7.1144E-07"
        iyz="1.6685E-08"
        izz="1.6594E-06" />
    </inertial>
    <visual>
      <origin
        xyz="0 0 0"
        rpy="0 0 0" />
      <geometry>
        <mesh
          filename="package://polaris_v2/meshes/CS2L.STL" />
      </geometry>
      <material
        name="Gray">
        <color
          rgba="0.89804 0.91765 0.92941 1" />
      </material>
    </visual>
    <collision>
      <origin
        xyz="0 0 0"
        rpy="0 0 0" />
      <geometry>
        <mesh
          filename="package://polaris_v2/meshes/CS2L.STL" />
      </geometry>
    </collision>
  </link>
  <joint
    name="CS2J"
    type="continuous">
    <origin
      xyz="0.38374 0.2125 -0.19774"
      rpy="0 0 0" />
    <parent
      link="base_link" />
    <child
      link="CS2L" />
    <axis
      xyz="0 0 1" />
    <limit
      effort="20"
      velocity="15" />
    <dynamics
      damping="0.2"
      friction="0" />
  </joint>
  <link
    name="CW2L">
    <inertial>
      <origin
        xyz="0 0 -5.5511E-17"
        rpy="0 0 0" />
      <mass
        value="0.007684" />
      <inertia
        ixx="5.0924E-07"
        ixy="2.0356E-08"
        ixz="-1.3859E-23"
        iyy="5.8873E-07"
        iyz="2.9859E-23"
        izz="5.0433E-07" />
    </inertial>
    <visual>
      <origin
        xyz="0 0 0"
        rpy="0 0 0" />
      <geometry>
        <mesh
          filename="package://polaris_v2/meshes/CW2L.STL" />
      </geometry>
      <material
        name="Black">
        <color
          rgba="0 0 0 1" />
      </material>
    </visual>
    <collision>
      <origin
        xyz="0 0 0"
        rpy="0 0 0" />
      <geometry>
        <mesh
          filename="package://polaris_v2/meshes/CW2L.STL" />
      </geometry>
    </collision>
  </link>
  <joint
    name="CW2J"
    type="continuous">
    <origin
      xyz="-0.0071887 0.0012196 -0.020775"
      rpy="0 0 0" />
    <parent
      link="CS2L" />
    <child
      link="CW2L" />
    <axis
      xyz="0 1 0" />
    <limit
      effort="20"
      velocity="15" />
    <dynamics
      damping="0.2"
      friction="0" />
  </joint>
  <link
    name="CS3L">
    <inertial>
      <origin
        xyz="-0.0010067 0.00010308 -0.0079289"
        rpy="0 0 0" />
      <mass
        value="0.012201" />
      <inertia
        ixx="1.3494E-06"
        ixy="-6.9225E-08"
        ixz="7.0821E-08"
        iyy="6.81E-07"
        iyz="-7.2487E-09"
        izz="1.6594E-06" />
    </inertial>
    <visual>
      <origin
        xyz="0 0 0"
        rpy="0 0 0" />
      <geometry>
        <mesh
          filename="package://polaris_v2/meshes/CS3L.STL" />
      </geometry>
      <material
        name="Gray">
        <color
          rgba="0.89804 0.91765 0.92941 1" />
      </material>
    </visual>
    <collision>
      <origin
        xyz="0 0 0"
        rpy="0 0 0" />
      <geometry>
        <mesh
          filename="package://polaris_v2/meshes/CS3L.STL" />
      </geometry>
    </collision>
  </link>
  <joint
    name="CS3J"
    type="continuous">
    <origin
      xyz="-0.38126 -0.2125 -0.19774"
      rpy="0 0 0" />
    <parent
      link="base_link" />
    <child
      link="CS3L" />
    <axis
      xyz="0 0 1" />
    <limit
      effort="20"
      velocity="15" />
    <dynamics
      damping="0.2"
      friction="0" />
  </joint>
  <link
    name="CW3L">
    <inertial>
      <origin
        xyz="-1.7347E-18 0 0"
        rpy="0 0 0" />
      <mass
        value="0.007684" />
      <inertia
        ixx="5.0526E-07"
        ixy="9.0562E-09"
        ixz="5.9133E-23"
        iyy="5.9271E-07"
        iyz="1.0492E-23"
        izz="5.0433E-07" />
    </inertial>
    <visual>
      <origin
        xyz="0 0 0"
        rpy="0 0 0" />
      <geometry>
        <mesh
          filename="package://polaris_v2/meshes/CW3L.STL" />
      </geometry>
      <material
        name="Black">
        <color
          rgba="0 0 0 1" />
      </material>
    </visual>
    <collision>
      <origin
        xyz="0 0 0"
        rpy="0 0 0" />
      <geometry>
        <mesh
          filename="package://polaris_v2/meshes/CW3L.STL" />
      </geometry>
    </collision>
  </link>
  <joint
    name="CW3J"
    type="continuous">
    <origin
      xyz="0.0072873 -0.00024416 -0.020775"
      rpy="0 0 0" />
    <parent
      link="CS3L" />
    <child
      link="CW3L" />
    <axis
      xyz="0 1 0" />
    <limit
      effort="20"
      velocity="15" />
    <dynamics
      damping="0.2"
      friction="0" />
  </joint>
  <link
    name="CS4L">
    <inertial>
      <origin
        xyz="-0.0010114 3.4348E-05 -0.0079289"
        rpy="0 0 0" />
      <mass
        value="0.012201" />
      <inertia
        ixx="1.3557E-06"
        ixy="-2.3217E-08"
        ixz="7.115E-08"
        iyy="6.747E-07"
        iyz="-2.4138E-09"
        izz="1.6594E-06" />
    </inertial>
    <visual>
      <origin
        xyz="0 0 0"
        rpy="0 0 0" />
      <geometry>
        <mesh
          filename="package://polaris_v2/meshes/CS4L.STL" />
      </geometry>
      <material
        name="Gray">
        <color
          rgba="0.89804 0.91765 0.92941 1" />
      </material>
    </visual>
    <collision>
      <origin
        xyz="0 0 0"
        rpy="0 0 0" />
      <geometry>
        <mesh
          filename="package://polaris_v2/meshes/CS4L.STL" />
      </geometry>
    </collision>
  </link>
  <joint
    name="CS4J"
    type="continuous">
    <origin
      xyz="-0.38126 0.2125 -0.19774"
      rpy="0 0 0" />
    <parent
      link="base_link" />
    <child
      link="CS4L" />
    <axis
      xyz="0 0 1" />
    <limit
      effort="20"
      velocity="15" />
    <dynamics
      damping="0.2"
      friction="0" />
  </joint>
  <link
    name="CW4L">
    <inertial>
      <origin
        xyz="0 0 -5.5511E-17"
        rpy="0 0 0" />
      <mass
        value="0.007684" />
      <inertia
        ixx="5.0444E-07"
        ixy="3.0371E-09"
        ixz="2.0261E-23"
        iyy="5.9353E-07"
        iyz="-1.5601E-24"
        izz="5.0433E-07" />
    </inertial>
    <visual>
      <origin
        xyz="0 0 0"
        rpy="0 0 0" />
      <geometry>
        <mesh
          filename="package://polaris_v2/meshes/CW4L.STL" />
      </geometry>
      <material
        name="Black">
        <color
          rgba="0 0 0 1" />
      </material>
    </visual>
    <collision>
      <origin
        xyz="0 0 0"
        rpy="0 0 0" />
      <geometry>
        <mesh
          filename="package://polaris_v2/meshes/CW4L.STL" />
      </geometry>
    </collision>
  </link>
  <joint
    name="CW4J"
    type="continuous">
    <origin
      xyz="0.007287 0.00025217 -0.020775"
      rpy="0 0 0" />
    <parent
      link="CS4L" />
    <child
      link="CW4L" />
    <axis
      xyz="0 1 0" />
    <limit
      effort="20"
      velocity="15" />
    <dynamics
      damping="0.2"
      friction="0" />
  </joint>
  
  <transmission name="Lifting_Link_trans">
    <type>transmission_interface/SimpleTransmission</type>
    <joint name="Lifting_Joint">
      <hardwareInterface>hardware_interface/PositionJointInterface</hardwareInterface>
    </joint>
    <actuator name="Lifting_Link_motor">
      <hardwareInterface>hardware_interface/PositionJointInterface</hardwareInterface>
      <mechanicalReduction>1</mechanicalReduction>
      <!-- Lineer motor için eklenebilecek parametreler -->
      <max_force>100</max_force>
      <max_velocity>0.5</max_velocity>
    </actuator>  
  </transmission>
  
  <gazebo>
    <plugin name="gazebo_ros_control" filename="libgazebo_ros_control.so">
      <robotNamespace>/</robotNamespace>
    </plugin>
  </gazebo>

  <!--Gazebo ortamında color, dumping(mu2), friction(mu1) gibi etkenleri tanımlamak amacıyla aşağıdaki kod dizilimi kullanılmıştır.-->
  <gazebo reference="base_link">
    <mu1>0.2</mu1>
    <mu2>0.2</mu2>
    <material>Gazebo/White</material>
  </gazebo>  

  <gazebo reference="Lidar_Link">
    <mu1>0.2</mu1>
    <mu2>0.2</mu2>
    <material>Gazebo/Black</material>
  </gazebo>  

  <gazebo reference="Camera_Link">
    <mu1>0.2</mu1>
    <mu2>0.2</mu2>
    <material>Gazebo/Gray</material>
  </gazebo>

  <gazebo reference="Lifting_Link">
    <mu1>0.2</mu1>
    <mu2>0.2</mu2>
    <material>Gazebo/Red</material>
  </gazebo>
  
  <gazebo reference="Left_Wheel_Link">
    <mu1>0.2</mu1>
    <mu2>0.2</mu2>
    <material>Gazebo/Red</material>
  </gazebo>
  
  <gazebo reference="Right_Wheel_Link">
    <mu1>0.2</mu1>
    <mu2>0.2</mu2>
    <material>Gazebo/Red</material>
  </gazebo>

  <gazebo reference="CS1L">
    <mu1>0</mu1>
    <mu2>0</mu2>
    <material>Gazebo/Gray</material>
  </gazebo>

  <gazebo reference="CS2L">
    <mu1>0</mu1>
    <mu2>0</mu2>
    <material>Gazebo/Gray</material>
  </gazebo>
  
  <gazebo reference="CS3L">
    <mu1>0</mu1>
    <mu2>0</mu2>
    <material>Gazebo/Gray</material>
  </gazebo>

  <gazebo reference="CS4L">
    <mu1>0</mu1>
    <mu2>0</mu2>
    <material>Gazebo/Gray</material>
  </gazebo>

  <gazebo reference="CW1L">
    <mu1>0</mu1>
    <mu2>0</mu2>
    <material>Gazebo/Black</material>
  </gazebo>

  <gazebo reference="CW2L">
    <mu1>0</mu1>
    <mu2>0</mu2>
    <material>Gazebo/Black</material>
  </gazebo>
  
  <gazebo reference="CW3L">
    <mu1>0</mu1>
    <mu2>0</mu2>
    <material>Gazebo/Black</material>
  </gazebo>

  <gazebo reference="CW4L">
    <mu1>0</mu1>
    <mu2>0</mu2>
    <material>Gazebo/Black</material>
  </gazebo>
    
<gazebo>
  <plugin name="differential_drive_controller" filename="libgazebo_ros_diff_drive.so">
    <updateRate>100.0</updateRate>
    <leftJoint>Left_Wheel_Joint</leftJoint>
    <rightJoint>Right_Wheel_Joint</rightJoint>
    <wheelSeparation>0.5</wheelSeparation>
    <wheelDiameter>0.17</wheelDiameter>
    <wheelAcceleration>1.0</wheelAcceleration>
    <wheelTorque>20</wheelTorque>
    <commandTopic>cmd_vel</commandTopic>
    <odometryTopic>odom</odometryTopic>
    <odometryFrame>odom</odometryFrame>
    <robotBaseFrame>base_link</robotBaseFrame>
    <publishWheelTF>false</publishWheelTF> <!-- Devre dışı bırakıldı -->
    <publishOdom>true</publishOdom>
    <publishWheelJointState>true</publishWheelJointState>
    <odometrySource>ENCODER</odometrySource>
    <rosDebugLevel>na</rosDebugLevel>
    <publishOdomTF>false</publishOdomTF> <!-- Devre dışı bırakıldı -->
    <publishTf>1</publishTf> <!-- Sadece bu etkin -->
    <max_velocity>15.0</max_velocity>
    <max_acceleration>15.0</max_acceleration>
    <covariance_x>0.0001</covariance_x>
    <covariance_y>0.0001</covariance_y>
    <covariance_yaw>0.01</covariance_yaw>
  </plugin>
</gazebo>

  
  
</robot>
